<mujoco model="cone-e">
  <compiler angle="radian" />
  <option integrator="implicitfast" cone="elliptic" impratio="10" gravity="0 0 -9.81" timestep="0.001" />
  <default>
    <default class="robot">
      <default class="motor">
        <joint />
        <motor />
      </default>
      <default class="steering_joint">
        <position kp="10" kv="1" inheritrange="1" />
        <joint frictionloss="0.001" range="-3.14159 3.14159" />
      </default>
      <default class="drive_joint">
        <velocity kv="1" />
        <joint frictionloss="0.001" />
      </default>
      <default class="visual">
        <geom material="visualgeom" type="mesh" contype="0" conaffinity="0" group="2" density="0"/>
      </default>
      <default class="collision">
        <geom type="capsule" condim="3" contype="0" conaffinity="1" priority="1" group="1" solref="0.005 1"
          friction="1 0.01 0.01" />
        <equality solimp="0.99 0.999 1e-05" solref="0.005 1" />
      </default>
      <default class="wheel">
        <!-- 4 is friction that opposes rotation around the contact normal -->
        <geom type="mesh" condim="4" contype="0" conaffinity="1" priority="1" group="1" solref="0.005 1"
          friction="1.2 0.005 0.005" />
      </default>
    </default>


    <default class="piper">
      <joint frictionloss="0.3" armature="0.005" />
      <position inheritrange="1" forcerange="-100 100" />
      <default class="collision_gripper">
        <geom type="mesh" group="3" friction="2 0.005 0.0001" density="100" />
      </default>
    </default>
  </default>


  <asset>
    <!-- base and lift assets -->
    <material name="base_material" rgba="1 0 0 1" />
    <material name="base_profile_short_material" rgba="0.701961 0.701961 0.701961 1" />
    <material name="Part_2_material" rgba="0.615686 0.811765 0.929412 1" />
    <material name="MK4_Colson_Hub_4_X_1.5_material" rgba="0.666667 0.698039 0.768627 1" />
    <material name="Lift_Middle_material" rgba="0.901961 0.901961 0.901961 1" />
    <material name="default_material" rgba="0.7 0.7 0.7 1" />

    <mesh name="base_profile_short.stl" file="meshes/base_profile_short.stl" />
    <mesh name="Part_2.stl" file="meshes/Part_2.stl" />
    <mesh name="MK4_Colson_Hub_4_X_1.5.stl" file="meshes/MK4_Colson_Hub_4_X_1.5.stl" />
    <mesh name="Part_2_2.stl" file="meshes/Part_2_2.stl" />
    <mesh name="MK4_Colson_Hub_4_X_1.5_2.stl" file="meshes/MK4_Colson_Hub_4_X_1.5_2.stl" />
    <mesh name="Part_2_3.stl" file="meshes/Part_2_3.stl" />
    <mesh name="MK4_Colson_Hub_4_X_1.5_3.stl" file="meshes/MK4_Colson_Hub_4_X_1.5_3.stl" />
    <mesh name="Part_2_4.stl" file="meshes/Part_2_4.stl" />
    <mesh name="MK4_Colson_Hub_4_X_1.5_4.stl" file="meshes/MK4_Colson_Hub_4_X_1.5_4.stl" />
    <mesh name="Lift_Middle.stl" file="meshes/Lift_Middle.stl" />
    <mesh name="Lift_Top.stl" file="meshes/Lift_Top.stl" />

    <!-- piper assets -->
    <material name="white" rgba="1 1 1 1" />
    <material name="gray" rgba="0.15 0.15 0.15 1" />
    <material name="light_gray" rgba="0.6 0.6 0.6 1" />
    <material name="light_blue" rgba="0.345 0.65 0.976 1" />
    <material name="black" rgba="0.05 0.05 0.05 1" />
    <material name="gray_mat" rgba="0.59 0.59 0.59 1" />
    <material name="dark_gray_mat" rgba="0.086 0.086 0.086 1" />
    <material name="light_medium_gray_mat" rgba="0.85 0.85 0.85 1" />

    <mesh name="link0" file="meshes/piper/link0.stl" />
    <mesh name="link1" file="meshes/piper/link1.stl" />
    <mesh name="link2" file="meshes/piper/link2.stl" />
    <mesh name="link3" file="meshes/piper/link3.stl" />
    <mesh name="link4" file="meshes/piper/link4.stl" />
    <mesh name="link5" file="meshes/piper/link5.stl" />
    <mesh name="link6" file="meshes/piper/link6.stl" />
    <mesh name="gripper_base" file="meshes/piper/gripper_base.stl" />
    <mesh name="gripper_body" file="meshes/piper/gripper_body.stl" scale="0.001 0.001 0.001" />
    <mesh name="iphone" file="meshes/piper/iphone.stl" scale="0.001 0.001 0.001" />
  </asset>

  <worldbody>
    <body name="base" pos="0.00000000 0.00000000 0.10477502" euler="0 1.57 0" childclass="robot">
      <freejoint name="floating_base" />
      <geom name="base_visual" pos="0 0 0" quat="1.0 0.0 0.0 0.0" material="base_material"
        type="sphere" size="0.01" class="visual" />
      <body name="base_profile_short" pos="0 0 0" quat="1.0 0.0 0.0 0.0">
        <inertial pos="-0.104952 -0.210077 0.000819" quat="1.0 0.0 0.0 0.0" mass="20.612589"
          diaginertia="0.321576 0.487585 0.4515" />
        <geom name="base_profile_short_collision" pos="0 0 0" quat="1.0 0.0 0.0 0.0" type="box"
          mesh="base_profile_short.stl" class="collision" />
        <geom name="base_profile_short_visual" pos="0 0 0" quat="1.0 0.0 0.0 0.0"
          material="base_profile_short_material" type="mesh" mesh="base_profile_short.stl"
          class="visual" />
        <body name="Part_2" pos="-0.028575 -0.053975 0.104775"
          quat="0.5000001633974483 -0.4999999999999733 -0.49999983660255165 0.4999999999999733">
          <joint name="front_left_steer" type="hinge" ref="0.0" class="steering_joint" axis="0 0 1" />
          <inertial pos="0.000006 0 -0.020456" quat="1.0 0.0 0.0 0.0" mass="0.671221"
            diaginertia="0.000668 0.000705 0.000812" />
          <geom name="Part_2_collision" pos="0 0 0" quat="1.0 0.0 0.0 0.0" type="mesh"
            mesh="Part_2.stl" class="collision" />
          <geom name="Part_2_visual" pos="0 0 0" quat="1.0 0.0 0.0 0.0" material="Part_2_material"
            type="mesh" mesh="Part_2.stl" class="visual" />
          <body name="MK4_Colson_Hub_4_X_1.5" pos="0.021272 0 -0.075425"
            quat="0.5000001633974483 -0.4999999999999733 -0.49999983660255165 0.4999999999999733">
            <joint name="drive_front_left" type="hinge" ref="0.0" class="drive_joint" axis="0 0 -1" />
            <inertial pos="0 0 0.019800" quat="1.0 0.0 0.0 0.0" mass="0.507297"
              diaginertia="0.000352 0.000352 0.000615" />
            <geom name="MK4_Colson_Hub_4_X_1.5_collision" pos="0 0 0" quat="1.0 0.0 0.0 0.0"
              type="mesh" mesh="MK4_Colson_Hub_4_X_1.5.stl" class="wheel" />
            <geom name="MK4_Colson_Hub_4_X_1.5_visual" pos="0 0 0" quat="1.0 0.0 0.0 0.0"
              material="MK4_Colson_Hub_4_X_1.5_material" type="mesh"
              mesh="MK4_Colson_Hub_4_X_1.5.stl" class="visual" />
          </body>
        </body>
        <body name="Part_2_2" pos="-0.028575 -0.053975 -0.104775"
          quat="0.5000001633974483 -0.4999999999999733 -0.49999983660255165 0.4999999999999733">
          <joint name="back_left_steer" type="hinge" ref="0.0" class="steering_joint" axis="0 0 1" />
          <inertial pos="0.000006 0 -0.020456" quat="1.0 0.0 0.0 0.0" mass="0.671221"
            diaginertia="0.000668 0.000705 0.000812" />
          <geom name="Part_2_2_collision" pos="0 0 0" quat="1.0 0.0 0.0 0.0" type="mesh"
            mesh="Part_2_2.stl" class="collision" />
          <geom name="Part_2_2_visual" pos="0 0 0" quat="1.0 0.0 0.0 0.0" material="Part_2_material"
            type="mesh" mesh="Part_2_2.stl" class="visual" />
          <body name="MK4_Colson_Hub_4_X_1.5_2" pos="0.021272 0 -0.075425"
            quat="0.5000001633974483 -0.4999999999999733 -0.49999983660255165 0.4999999999999733">
            <joint name="drive_back_left" type="hinge" ref="0.0" class="drive_joint" axis="0 0 -1" />
            <inertial pos="0 0 0.019800" quat="1.0 0.0 0.0 0.0" mass="0.507297"
              diaginertia="0.000352 0.000352 0.000615" />
            <geom name="MK4_Colson_Hub_4_X_1.5_2_collision" pos="0 0 0" quat="1.0 0.0 0.0 0.0"
              type="mesh" mesh="MK4_Colson_Hub_4_X_1.5_2.stl" class="wheel" />
            <geom name="MK4_Colson_Hub_4_X_1.5_2_visual" pos="0 0 0" quat="1.0 0.0 0.0 0.0"
              material="MK4_Colson_Hub_4_X_1.5_material" type="mesh"
              mesh="MK4_Colson_Hub_4_X_1.5_2.stl" class="visual" />
          </body>
        </body>
        <body name="Part_2_3" pos="-0.028575 -0.365125 0.104775"
          quat="0.5000001633974483 -0.4999999999999733 -0.49999983660255165 0.4999999999999733">
          <joint name="front_right_steer" type="hinge" ref="0.0" class="steering_joint" axis="0 0 1" />
          <inertial pos="0.000006 0 -0.020456" quat="1.0 0.0 0.0 0.0" mass="0.671221"
            diaginertia="0.000668 0.000705 0.000812" />
          <geom name="Part_2_3_collision" pos="0 0 0" quat="1.0 0.0 0.0 0.0" type="mesh"
            mesh="Part_2_3.stl" class="collision" />
          <geom name="Part_2_3_visual" pos="0 0 0" quat="1.0 0.0 0.0 0.0" material="Part_2_material"
            type="mesh" mesh="Part_2_3.stl" class="visual" />
          <body name="MK4_Colson_Hub_4_X_1.5_3" pos="0.021272 0 -0.075425"
            quat="0.5000001633974483 -0.4999999999999733 -0.49999983660255165 0.4999999999999733">
            <joint name="drive_front_right" type="hinge" ref="0.0" class="drive_joint" axis="0 0 -1" />
            <inertial pos="0 0 0.019800" quat="1.0 0.0 0.0 0.0" mass="0.507297"
              diaginertia="0.000352 0.000352 0.000615" />
            <geom name="MK4_Colson_Hub_4_X_1.5_3_collision" pos="0 0 0" quat="1.0 0.0 0.0 0.0"
              type="mesh" mesh="MK4_Colson_Hub_4_X_1.5_3.stl" class="wheel" />
            <geom name="MK4_Colson_Hub_4_X_1.5_3_visual" pos="0 0 0" quat="1.0 0.0 0.0 0.0"
              material="MK4_Colson_Hub_4_X_1.5_material" type="mesh"
              mesh="MK4_Colson_Hub_4_X_1.5_3.stl" class="visual" />
          </body>
        </body>
        <body name="Part_2_4" pos="-0.028575 -0.365125 -0.104775"
          quat="0.5000001633974483 -0.4999999999999733 -0.49999983660255165 0.4999999999999733">
          <joint name="back_right_steer" type="hinge" ref="0.0" class="steering_joint" axis="0 0 1" />
          <inertial pos="0.000006 0 -0.020456" quat="1.0 0.0 0.0 0.0" mass="0.671221"
            diaginertia="0.000668 0.000705 0.000812" />
          <geom name="Part_2_4_collision" pos="0 0 0" quat="1.0 0.0 0.0 0.0" type="mesh"
            mesh="Part_2_4.stl" class="collision" />
          <geom name="Part_2_4_visual" pos="0 0 0" quat="1.0 0.0 0.0 0.0" material="Part_2_material"
            type="mesh" mesh="Part_2_4.stl" class="visual" />
          <body name="MK4_Colson_Hub_4_X_1.5_4" pos="0.021272 0 -0.075425"
            quat="0.5000001633974483 -0.4999999999999733 -0.49999983660255165 0.4999999999999733">
            <joint name="drive_back_right" type="hinge" ref="0.0" class="drive_joint" axis="0 0 -1" />
            <inertial pos="0 0 0.019800" quat="1.0 0.0 0.0 0.0" mass="0.507297"
              diaginertia="0.000352 0.000352 0.000615" />
            <geom name="MK4_Colson_Hub_4_X_1.5_4_collision" pos="0 0 0" quat="1.0 0.0 0.0 0.0"
              type="mesh" mesh="MK4_Colson_Hub_4_X_1.5_4.stl" class="wheel" />
            <geom name="MK4_Colson_Hub_4_X_1.5_4_visual" pos="0 0 0" quat="1.0 0.0 0.0 0.0"
              material="MK4_Colson_Hub_4_X_1.5_material" type="mesh"
              mesh="MK4_Colson_Hub_4_X_1.5_4.stl" class="visual" />
          </body>
        </body>
        <body name="Lift_Middle" pos="-0.509400 -0.209550 0.000317"
          quat="-1.2247452309842457e-07 -0.7071068967259713 -1.22474483074382e-07 0.7071066656470838">
          <joint name="Slider_1" type="slide" ref="0.0" class="motor" range="0 0.208000"
            axis="0 0 1" />
          <inertial pos="0 0 -0.104000" quat="1.0 0.0 0.0 0.0" mass="1.460741"
            diaginertia="0.007792 0.007792 0.005051" />
          <geom name="Lift_Middle_collision" pos="0 0 0" quat="1.0 0.0 0.0 0.0" type="mesh"
            mesh="Lift_Middle.stl" class="collision" />
          <geom name="Lift_Middle_visual" pos="0 0 0" quat="1.0 0.0 0.0 0.0"
            material="Lift_Middle_material" type="mesh" mesh="Lift_Middle.stl" class="visual" />
          <body name="Lift_Top" pos="0 0 0" quat="1.0 0.0 0.0 0.0">
            <joint name="Slider_2" type="slide" ref="0.0" class="motor" range="0 0.208000"
              axis="0 0 1" />
            <inertial pos="0.000005 -0.000004 -0.024234" quat="1.0 0.0 0.0 0.0" mass="4.435110"
              diaginertia="0.042873 0.040894 0.045651" />
            <geom name="Lift_Top_collision" pos="0 0 0" quat="1.0 0.0 0.0 0.0" type="mesh"
              mesh="Lift_Top.stl" class="collision" />
            <geom name="Lift_Top_visual" pos="0 0 0" quat="1.0 0.0 0.0 0.0"
              material="Lift_Middle_material" type="mesh" mesh="Lift_Top.stl" class="visual" />

              <body name="left_arm_link0" euler="0.7854 0 3.14" pos="-0.005 -0.0925 0.0575" childclass="piper" gravcomp="1">
                <inertial pos="-0.00473641 2.56829e-05 0.0414515"
                  quat="0.70428 0.034288 0.0339756 0.708279" mass="1.02"
                  diaginertia="0.00282612 0.00269117 0.000879394" />
                <geom class="visual" mesh="link0" material="light_medium_gray_mat" />
                <geom class="collision" mesh="link0" />
                <body name="left_arm_link1" pos="0 0 0.123" gravcomp="1">
                  <inertial pos="0.000121505 0.000104632 -0.00438597"
                    quat="0.682111 0.730899 0.0143111 -0.0175062" mass="0.71"
                    diaginertia="0.000489262 0.000439887 0.000404551" />
                  <joint name="left_arm_joint1" pos="0 0 0" axis="0 0 1" range="-2.61 2.61" />
                  <geom class="visual" mesh="link1" material="gray_mat" />
                  <geom class="collision" mesh="link1" />
                  <body name="left_arm_link2" quat="0.0480084 -0.0480134 -0.705476 -0.705474" gravcomp="1">
                    <inertial pos="0.198666 -0.0109269 0.00142122"
                      quat="0.510131 0.475585 0.525075 0.48773" mass="1.17"
                      diaginertia="0.0679032 0.067745 0.00111966" />
                    <joint name="left_arm_joint2" axis="0 0 1" range="0 3.13" />
                    <geom class="visual" mesh="link2" material="light_medium_gray_mat" />
                    <geom class="collision" mesh="link2" />
                    <body name="left_arm_link3" pos="0.28503 0 0" quat="0.623996 0 0 -0.781427" gravcomp="1">
                      <inertial pos="-0.0202738 -0.133915 -0.000458683"
                        quat="0.706282 0.705111 0.0532202 0.0339395" mass="0.5"
                        diaginertia="0.0138227 0.0138032 0.000244685" />
                      <joint name="left_arm_joint3" axis="0 0 1" range="-2.965 0" />
                      <geom class="visual" mesh="link3" material="gray_mat" />
                      <geom class="collision" mesh="link3" />
                      <body name="left_arm_link4" pos="-0.021984 -0.25075 0" quat="0.707105 0.707108 0 0"
                        gravcomp="1">
                        <inertial pos="-9.66636e-05 0.000876064 -0.00496881"
                          quat="0.714689 -0.0948484 0.0635223 0.690064" mass="0.38"
                          diaginertia="0.000191586 0.000185052 0.000152863" />
                        <joint name="left_arm_joint4" axis="0 0 1" range="-1.74 1.74" />
                        <geom class="visual" mesh="link4"
                          material="light_medium_gray_mat" />
                        <geom class="collision" mesh="link4" />
                        <body name="left_arm_link5" quat="0.707105 -0.707108 0 0" gravcomp="1">
                          <inertial pos="-4.10554e-05 -0.0566487 -0.00372058"
                            quat="0.709589 0.704614 0.00134613 -0.00132656" mass="0.383"
                            diaginertia="0.00166169 0.00164328 0.000185028" />
                          <joint name="left_arm_joint5" axis="0 0 1" range="-1.2 1.2" />
                          <geom class="visual" mesh="link5" material="gray_mat" />
                          <geom class="collision" mesh="link5" />
                          <body name="left_arm_link6" pos="8.8259e-05 -0.091 0"
                            quat="0.707105 0.707108 0 0" gravcomp="1">
                            <inertial pos="-8.82591e-05 9.05984e-06 -0.002"
                              quat="0.5 0.5 -0.5 0.5" mass="0.0069909"
                              diaginertia="1.06739e-06 5.73016e-07 5.73016e-07" />
                            <joint name="left_arm_joint6" axis="0 0 1" range="-3 3" />
                            <geom class="visual" mesh="link6"
                              material="light_medium_gray_mat" />
                            <geom class="collision" mesh="link6" />
                            <!-- 7.8mm -->
                            <body name="left_arm_gripper_base" pos="0.0275 0.01875 0.0798"
                              euler="3.14 -1.57 0" gravcomp="1">
                              <inertial pos="-0.000183807 8.05033e-05 0.0321437"
                                quat="0.999976 9.08444e-05 0.00689649 0.000788512"
                                mass="0.45"
                                diaginertia="0.000929442 0.000714469 0.000394318" />
                              <geom mesh="gripper_body" class="visual" material="white" />
                              <geom mesh="gripper_body" class="collision_gripper" />

                              <body name="left_arm_iphone_body" pos="-0.0075 0.015 0.017" euler="0 0 1.57"
                                gravcomp="1">
                                <geom mesh="iphone" class="visual" material="gray" />
                                <geom mesh="iphone" class="collision" />

                                <body name="left_arm_camera_body" pos="0.0 -0.036 0.1"
                                  euler="-0.2617993878 3.14159265359 0.0" gravcomp="1">
                                  <site name="left_arm_ee" pos="0.0 0.0 0.0" />
                                  <geom type="box" size="0.01 0.01 0.01" rgba="0.1 0.5 0.1 0" contype="0" conaffinity="0" />
                                  <camera name="left_arm_egocentric" mode="fixed" fovy="53.1" />
                                </body>
                              </body>
                            </body>
                          </body>
                        </body>
                      </body>
                    </body>
                  </body>
                </body>
              </body>

            <body name="right_arm_link0" euler="-0.7854 0 3.14" pos="-0.005 0.0925 0.0575" childclass="piper" gravcomp="1">
              <inertial pos="-0.00473641 2.56829e-05 0.0414515"
                quat="0.70428 0.034288 0.0339756 0.708279" mass="1.02"
                diaginertia="0.00282612 0.00269117 0.000879394" />
              <geom class="visual" mesh="link0" material="light_medium_gray_mat" />
              <geom class="collision" mesh="link0" />
              <body name="right_arm_link1" pos="0 0 0.123" gravcomp="1">
                <inertial pos="0.000121505 0.000104632 -0.00438597"
                  quat="0.682111 0.730899 0.0143111 -0.0175062" mass="0.71"
                  diaginertia="0.000489262 0.000439887 0.000404551" />
                <joint name="right_arm_joint1" pos="0 0 0" axis="0 0 1" range="-2.61 2.61" />
                <geom class="visual" mesh="link1" material="gray_mat" />
                <geom class="collision" mesh="link1" />
                <body name="right_arm_link2" quat="0.0480084 -0.0480134 -0.705476 -0.705474" gravcomp="1">
                  <inertial pos="0.198666 -0.0109269 0.00142122"
                    quat="0.510131 0.475585 0.525075 0.48773" mass="1.17"
                    diaginertia="0.0679032 0.067745 0.00111966" />
                  <joint name="right_arm_joint2" axis="0 0 1" range="0 3.13" />
                  <geom class="visual" mesh="link2" material="light_medium_gray_mat" />
                  <geom class="collision" mesh="link2" />
                  <body name="right_arm_link3" pos="0.28503 0 0" quat="0.623996 0 0 -0.781427" gravcomp="1">
                    <inertial pos="-0.0202738 -0.133915 -0.000458683"
                      quat="0.706282 0.705111 0.0532202 0.0339395" mass="0.5"
                      diaginertia="0.0138227 0.0138032 0.000244685" />
                    <joint name="right_arm_joint3" axis="0 0 1" range="-2.965 0" />
                    <geom class="visual" mesh="link3" material="gray_mat" />
                    <geom class="collision" mesh="link3" />
                    <body name="right_arm_link4" pos="-0.021984 -0.25075 0" quat="0.707105 0.707108 0 0"
                      gravcomp="1">
                      <inertial pos="-9.66636e-05 0.000876064 -0.00496881"
                        quat="0.714689 -0.0948484 0.0635223 0.690064" mass="0.38"
                        diaginertia="0.000191586 0.000185052 0.000152863" />
                      <joint name="right_arm_joint4" axis="0 0 1" range="-1.74 1.74" />
                      <geom class="visual" mesh="link4"
                        material="light_medium_gray_mat" />
                      <geom class="collision" mesh="link4" />
                      <body name="right_arm_link5" quat="0.707105 -0.707108 0 0" gravcomp="1">
                        <inertial pos="-4.10554e-05 -0.0566487 -0.00372058"
                          quat="0.709589 0.704614 0.00134613 -0.00132656" mass="0.383"
                          diaginertia="0.00166169 0.00164328 0.000185028" />
                        <joint name="right_arm_joint5" axis="0 0 1" range="-1.2 1.2" />
                        <geom class="visual" mesh="link5" material="gray_mat" />
                        <geom class="collision" mesh="link5" />
                        <body name="right_arm_link6" pos="8.8259e-05 -0.091 0"
                          quat="0.707105 0.707108 0 0" gravcomp="1">
                          <inertial pos="-8.82591e-05 9.05984e-06 -0.002"
                            quat="0.5 0.5 -0.5 0.5" mass="0.0069909"
                            diaginertia="1.06739e-06 5.73016e-07 5.73016e-07" />
                          <joint name="right_arm_joint6" axis="0 0 1" range="-3 3" />
                          <geom class="visual" mesh="link6"
                            material="light_medium_gray_mat" />
                          <geom class="collision" mesh="link6" />
                          <!-- 7.8mm -->
                          <body name="right_arm_gripper_base" pos="0.0275 0.01875 0.0798"
                            euler="3.14 -1.57 0" gravcomp="1">
                            <inertial pos="-0.000183807 8.05033e-05 0.0321437"
                              quat="0.999976 9.08444e-05 0.00689649 0.000788512"
                              mass="0.45"
                              diaginertia="0.000929442 0.000714469 0.000394318" />
                            <geom mesh="gripper_body" class="visual" material="white" />
                            <geom mesh="gripper_body" class="collision_gripper" />

                            <body name="right_arm_iphone_body" pos="-0.0075 0.015 0.017" euler="0 0 1.57"
                              gravcomp="1">
                              <geom mesh="iphone" class="visual" material="gray" />
                              <geom mesh="iphone" class="collision" />

                              <body name="right_arm_camera_body" pos="0.0 -0.036 0.1"
                                euler="-0.2617993878 3.14159265359 0.0" gravcomp="1">
                                <site name="right_arm_ee" pos="0.0 0.0 0.0" />
                                <geom type="box" size="0.01 0.01 0.01" rgba="0.1 0.5 0.1 0" contype="0" conaffinity="0" />
                                <camera name="right_arm_egocentric" mode="fixed" fovy="53.1" />
                              </body>
                            </body>
                          </body>
                        </body>
                      </body>
                    </body>
                  </body>
                </body>
              </body>
            </body>
          </body>
        </body>
      </body>
      <site name="base_site" pos="0 0 0" quat="1 0 0 0" />
      <camera name="front_camera" mode="track" fovy="90.0"
        quat="4.329780281177467e-17 4.329780281177466e-17 0.7071067811865475 0.7071067811865476"
        pos="0.0 2.0 0.5" />
      <camera name="side_camera" mode="track" fovy="90.0"
        quat="-0.5 -0.4999999999999999 0.5 0.5000000000000001" pos="-2.0 0.0 0.5" />
    </body>
  </worldbody>

  <actuator>
    <position name="front_left_steer_ctrl" joint="front_left_steer" class="steering_joint" />
    <velocity name="drive_front_left_ctrl" joint="drive_front_left" class="drive_joint" />
    <position name="back_left_steer_ctrl" joint="back_left_steer" class="steering_joint" />
    <velocity name="drive_back_left_ctrl" joint="drive_back_left" class="drive_joint" />
    <position name="front_right_steer_ctrl" joint="front_right_steer" class="steering_joint" />
    <velocity name="drive_front_right_ctrl" joint="drive_front_right" class="drive_joint" />
    <position name="back_right_steer_ctrl" joint="back_right_steer" class="steering_joint" />
    <velocity name="drive_back_right_ctrl" joint="drive_back_right" class="drive_joint" />
    <motor name="Slider_1_ctrl" joint="Slider_1" class="motor" />
    <motor name="Slider_2_ctrl" joint="Slider_2" class="motor" />

    <!-- Piper actuators -->
     <!-- Left arm -->
    <position name="left_arm_joint1_pos" joint="left_arm_joint1" class="piper" kp="10" kv="1" />
    <position name="left_arm_joint2_pos" joint="left_arm_joint2" class="piper" kp="10" kv="1" />
    <position name="left_arm_joint3_pos" joint="left_arm_joint3" class="piper" kp="10" kv="1" />
    <position name="left_arm_joint4_pos" joint="left_arm_joint4" class="piper" kp="5" kv="1" />
    <position name="left_arm_joint5_pos" joint="left_arm_joint5" class="piper" kp="5" kv="1" />
    <position name="left_arm_joint6_pos" joint="left_arm_joint6" class="piper" kp="5" kv="1" />
     <!-- Right arm -->
    <position name="right_arm_joint1_pos" joint="right_arm_joint1" class="piper" kp="10" kv="1" />
    <!-- <velocity name="joint1_vel" joint="joint1" kv="5" />
    <motor name="joint1_torque" joint="joint1" /> -->
    <position name="right_arm_joint2_pos" joint="right_arm_joint2" class="piper" kp="10" kv="1" />
    <!-- <velocity name="joint2_vel" joint="joint2" kv="5" />
    <motor name="joint2_torque" joint="joint2" /> -->
    <position name="right_arm_joint3_pos" joint="right_arm_joint3" class="piper" kp="10" kv="1" />
    <!-- <velocity name="joint3_vel" joint="joint3" kv="5" />
    <motor name="joint3_torque" joint="joint3" /> -->
    <position name="right_arm_joint4_pos" joint="right_arm_joint4" class="piper" kp="5" kv="1" />
    <!-- <velocity name="joint4_vel" joint="joint4" kv="5" />
    <motor name="joint4_torque" joint="joint4" /> -->
    <position name="right_arm_joint5_pos" joint="right_arm_joint5" class="piper" kp="5" kv="1" />
    <!-- <velocity name="joint5_vel" joint="joint5" kv="1.5" />
    <motor name="joint5_torque" joint="joint5" /> -->
    <position name="right_arm_joint6_pos" joint="right_arm_joint6" class="piper" kp="5" kv="1" />
    <!-- <velocity name="joint6_vel" joint="joint6" kv="1.5" />
    <motor name="joint6_torque" joint="joint6" /> -->
  </actuator>

  <contact>
    <exclude body1="left_arm_link0" body2="left_arm_link1" />
    <exclude body1="right_arm_link0" body2="right_arm_link1" />
    <exclude body1="Lift_Top" body2="left_arm_link0" />
    <exclude body1="Lift_Top" body2="right_arm_link0" />
    <exclude body1="base_profile_short" body2="Part_2" />
    <exclude body1="base_profile_short" body2="Part_2_2" />
    <exclude body1="Part_2" body2="MK4_Colson_Hub_4_X_1.5" />
    <exclude body1="base_profile_short" body2="Part_2_3" />
    <exclude body1="Part_2_2" body2="MK4_Colson_Hub_4_X_1.5_2" />
    <exclude body1="base_profile_short" body2="Part_2_4" />
    <exclude body1="base_profile_short" body2="Lift_Middle" />
    <exclude body1="Part_2_3" body2="MK4_Colson_Hub_4_X_1.5_3" />
    <exclude body1="Part_2_4" body2="MK4_Colson_Hub_4_X_1.5_4" />
    <exclude body1="Lift_Middle" body2="Lift_Top" />
  </contact>

  <sensor>
    <framepos name="base_site_pos" objtype="site" objname="base_site" />
    <framequat name="base_site_quat" objtype="site" objname="base_site" />
    <framelinvel name="base_site_linvel" objtype="site" objname="base_site" />
    <frameangvel name="base_site_angvel" objtype="site" objname="base_site" />
    <velocimeter name="base_site_vel" site="base_site" />
  </sensor>
</mujoco>