<mujoco>
  <!--
    Second Piper arm (left) for dual-arm lab scene.
    All names prefixed with "left_" to avoid conflicts with piper.xml.
    No assets defined - reuses meshes/materials from piper.xml.
    Position set via base body pos attribute.
  -->

  <worldbody>
    <light name="left_spotlight" mode="targetbodycom" target="left_gripper_base" pos="0 0 1"/>
    <body name="left_base_link" pos="0.23 0.68 0" euler="0 0 -1.5708" childclass="piper" gravcomp="1">
      <inertial pos="-0.00979275 1.82906e-06 0.04101" quat="0.692988 -0.137524 -0.137826 0.69416" mass="0.162549"
        diaginertia="0.000269445 0.000227478 0.000221437"/>
      <geom class="visual" density="0" mesh="base_link" material="gray_mat"/>
      <geom class="collision" mesh="base_link"/>
      <body name="left_link1" pos="0 0 0.123" quat="0.707105 0 0 -0.707108" gravcomp="1">
        <inertial pos="0.00131676 0.000310289 -0.00922875" quat="0.557105 0.432155 0.377373 0.600388" mass="0.097868"
          diaginertia="9.25942e-05 8.3083e-05 7.69469e-05"/>
        <joint name="left_joint1" axis="0 0 1" range="-2.618 2.618"/>
        <geom class="visual" density="0" mesh="link1" material="gray_mat"/>
        <geom class="collision" mesh="link1"/>
        <body name="left_link2" quat="0.499998 0.5 -0.500002 -0.5" gravcomp="1">
          <inertial pos="0.148794 -0.00242027 0.00175155" quat="-0.0249063 0.70684 0.00803509 0.706889" mass="0.290889"
            diaginertia="0.00177549 0.00173142 0.00014552"/>
          <joint name="left_joint2" axis="0 0 1" range="0 3.14"/>
          <geom mesh="link2_0" material="gray_mat" class="visual"/>
          <geom mesh="link2_1" material="darker_gray_mat" class="visual"/>
          <geom mesh="link2_2" material="darker_gray_mat" class="visual"/>
          <geom mesh="link2_3" material="dark_gray_mat" class="visual"/>
          <geom mesh="link2_4" material="dark_gray_mat" class="visual"/>
          <geom mesh="link2_5" material="red_mat" class="visual"/>
          <geom mesh="link2_6" material="dark_gray_mat" class="visual"/>
          <geom mesh="link2_7" material="gray_mat" class="visual"/>
          <geom mesh="link2_8" material="red_mat" class="visual"/>
          <geom mesh="link2_9" material="red_mat" class="visual"/>
          <geom mesh="link2_10" material="gray_mat" class="visual"/>
          <geom mesh="link2_11" material="red_mat" class="visual"/>
          <geom mesh="link2_12" material="red_mat" class="visual"/>
          <geom mesh="link2_13" material="red_mat" class="visual"/>
          <geom mesh="link2_14" material="red_mat" class="visual"/>
          <geom mesh="link2_15" material="red_mat" class="visual"/>
          <geom mesh="link2_16" material="red_mat" class="visual"/>
          <geom mesh="link2_17" material="red_mat" class="visual"/>
          <geom mesh="link2_18" material="red_mat" class="visual"/>
          <geom mesh="link2_19" material="red_mat" class="visual"/>
          <geom mesh="link2_20" material="red_mat" class="visual"/>
          <geom mesh="link2_21" material="gray_mat" class="visual"/>
          <geom mesh="link2_22" material="red_mat" class="visual"/>
          <geom mesh="link2_23" material="red_mat" class="visual"/>
          <geom mesh="link2_24" material="red_mat" class="visual"/>
          <geom mesh="link2_25" material="dark_gray_mat" class="visual"/>
          <geom mesh="link2_26" material="red_mat" class="visual"/>
          <geom mesh="link2_27" material="darker_gray_mat" class="visual"/>
          <geom mesh="link2_28" material="darker_gray_mat" class="visual"/>
          <geom mesh="link2_29" material="darker_gray_mat" class="visual"/>
          <geom mesh="link2_30" material="darker_gray_mat" class="visual"/>
          <geom mesh="link2_31" material="light_medium_gray_mat" class="visual"/>
          <geom mesh="link2" class="collision"/>
          <body name="left_link3" pos="0.28358 0.028726 0" quat="0.998726 0 0 0.0504536" gravcomp="1">
            <inertial pos="-0.0996835 0.0349477 0.000508026" quat="0.0777021 0.702287 -0.0990541 0.700674"
              mass="0.290848" diaginertia="0.000241946 0.000222224 0.000100384"/>
            <joint name="left_joint3" pos="0 0 0" axis="0 0 1" range="-2.697 0"/>
            <geom mesh="link3_0" material="darker_gray_mat" class="visual"/>
            <geom mesh="link3_1" material="red_mat" class="visual"/>
            <geom mesh="link3_2" material="gray_mat" class="visual"/>
            <geom mesh="link3_3" material="gray_mat" class="visual"/>
            <geom mesh="link3_4" material="gray_mat" class="visual"/>
            <geom mesh="link3_5" material="gray_mat" class="visual"/>
            <geom mesh="link3_7" material="darker_gray_mat" class="visual"/>
            <geom mesh="link3_8" material="white_mat" class="visual"/>
            <geom mesh="link3_9" material="red_mat" class="visual"/>
            <geom mesh="link3_10" material="white_mat" class="visual"/>
            <geom mesh="link3_11" material="white_mat" class="visual"/>
            <geom mesh="link3_12" material="white_mat" class="visual"/>
            <geom mesh="link3_13" material="white_mat" class="visual"/>
            <geom mesh="link3_14" material="gray_mat" class="visual"/>
            <geom mesh="link3_15" material="gray_mat" class="visual"/>
            <geom mesh="link3_16" material="gray_mat" class="visual"/>
            <geom mesh="link3_17" material="gray_mat" class="visual"/>
            <geom mesh="link3_18" material="gray_mat" class="visual"/>
            <geom mesh="link3_19" material="gray_mat" class="visual"/>
            <geom mesh="link3_20" material="gray_mat" class="visual"/>
            <geom mesh="link3_21" material="gray_mat" class="visual"/>
            <geom mesh="link3_22" material="gray_mat" class="visual"/>
            <geom mesh="link3_23" material="gray_mat" class="visual"/>
            <geom mesh="link3_24" material="gray_mat" class="visual"/>
            <geom mesh="link3_25" material="gray_mat" class="visual"/>
            <geom mesh="link3_26" material="gray_mat" class="visual"/>
            <geom mesh="link3_27" material="gray_mat" class="visual"/>
            <geom mesh="link3_28" material="gray_mat" class="visual"/>
            <geom mesh="link3" class="collision"/>
            <body name="left_link4" pos="-0.24221 0.068514 0" quat="0.544767 -0.544769 -0.450809 0.450808" gravcomp="1">
              <inertial pos="0.000276465 -0.00102804 -0.00472831" quat="0.492305 0.505285 0.503294 0.499017"
                mass="0.127087" diaginertia="4.87057e-05 4.10595e-05 3.82001e-05"/>
              <joint name="left_joint4" axis="0 0 1" range="-1.832 1.832"/>
              <geom mesh="link4_2" material="gray_mat" class="visual"/>
              <geom mesh="link4_3" material="darker_gray_mat" class="visual"/>
              <geom mesh="link4_4" material="gray_mat" class="visual"/>
              <geom mesh="link4_5" material="gray_mat" class="visual"/>
              <geom mesh="link4_6" material="gray_mat" class="visual"/>
              <geom mesh="link4" class="collision"/>
              <body name="left_link5" quat="0.707105 0.707108 0 0" gravcomp="1">
                <inertial pos="8.82262e-05 0.0566829 -0.0019612" quat="0.507447 0.490986 0.506887 0.494466"
                  mass="0.144711" diaginertia="0.001 0.001 0.001"/>
                <joint name="left_joint5" axis="0 0 1" range="-1.22 1.22"/>
                <geom mesh="link5_2" material="black_mat" class="visual"/>
                <geom mesh="link5_3" material="black_mat" class="visual"/>
                <geom mesh="link5_4" material="darker_gray_mat" class="visual"/>
                <geom mesh="link5_5" material="gray_mat" class="visual"/>
                <geom mesh="link5_6" material="light_gray_mat" class="visual"/>
                <geom mesh="link5_7" material="gray_mat" class="visual"/>
                <geom mesh="link5_8" material="gray_mat" class="visual"/>
                <geom mesh="link5" class="collision"/>

                <body name="left_link6_mount" pos="0 0.091 0.0014165" quat="0 0 -0.707105 -0.707108" gravcomp="1">
                  <body name="left_gripper_base" gravcomp="1">
                    <body name="left_gripper" euler="0 0 0" gravcomp="1">
                      <body name="left_gripper_align" pos="0 0 0" euler="0 1.5708 0" gravcomp="1">
                        <inertial pos="-0.000183807 8.05033e-05 0.0321437"
                          quat="0.999976 9.08444e-05 0.00689649 0.000788512"
                          mass="0.45"
                          diaginertia="0.000929442 0.000714469 0.000394318"/>
                        <!-- Fixed housing -->
                        <geom mesh="gripper_housing" class="visual" material="light_blue" euler="3.14159265359 0 0"/>
                        <geom mesh="gripper_housing" class="collision_gripper" euler="3.14159265359 0 0"/>

                        <!-- Upper blade -->
                        <body name="left_upper_jaw" pos="-0.0308 -0.0051 -0.0302" gravcomp="1">
                          <joint name="left_upper_jaw_joint" type="hinge" axis="0 0 1" range="0 0.99" ref="0.66" damping="2" stiffness="50" springref="0" frictionloss="0.5" armature="0.01"/>
                          <geom mesh="gripper_upper" class="visual" material="light_blue"
                                euler="3.14159265359 0 0" pos="0.0308 0.0051 0.0302"/>
                          <geom mesh="gripper_upper" class="collision_gripper"
                                euler="3.14159265359 0 0" pos="0.0308 0.0051 0.0302"/>
                        </body>

                        <!-- Lower blade -->
                        <body name="left_lower_jaw" pos="-0.0314 -0.0321 -0.0275" gravcomp="1">
                          <joint name="left_lower_jaw_joint" type="hinge" axis="0 0 1" range="-0.99 0" ref="-0.66" damping="2" stiffness="50" springref="0" frictionloss="0.5" armature="0.01"/>
                          <geom mesh="gripper_lower" class="visual" material="light_blue"
                                euler="3.14159265359 0 0" pos="0.0314 0.0321 0.0275"/>
                          <geom mesh="gripper_lower" class="collision_gripper"
                                euler="3.14159265359 0 0" pos="0.0314 0.0321 0.0275"/>
                        </body>

                        <body name="left_iphone_body" pos="-0.0075 -0.015 -0.017" euler="3.14159265359 0 1.5708" gravcomp="1">
                          <geom mesh="iphone" class="visual" material="gray"/>
                          <geom mesh="iphone" class="collision"/>
                          <body name="left_camera_body" pos="0.0 -0.036 0.1"
                            euler="-0.2617993878 3.14159265359 0.0" gravcomp="1">
                            <site name="left_ee" pos="0.0 0.0 0.0"/>
                            <geom type="box" size="0.01 0.01 0.01" rgba="0.1 0.5 0.1 0" contype="0" conaffinity="0"/>
                            <camera name="left_egocentric" mode="fixed" fovy="53.1"/>
                          </body>
                        </body>
                      </body>
                    </body>
                  </body>
                </body>
              </body>
            </body>
          </body>
        </body>
      </body>
    </body>
  </worldbody>

  <contact>
    <exclude body1="left_base_link" body2="left_link1"/>
  </contact>

  <equality>
    <joint joint1="left_upper_jaw_joint" joint2="left_lower_jaw_joint" polycoef="0 -1 0 0 0"/>
  </equality>

  <actuator>
    <position name="left_joint1" joint="left_joint1" class="piper" kp="80" kv="5"/>
    <position name="left_joint2" joint="left_joint2" class="piper" kp="80" kv="5"/>
    <position name="left_joint3" joint="left_joint3" class="piper" kp="80" kv="5"/>
    <position name="left_joint4" joint="left_joint4" class="piper" kp="40" kv="5"/>
    <position name="left_joint5" joint="left_joint5" class="piper" kp="10" kv="1.5"/>
    <position name="left_gripper" joint="left_upper_jaw_joint" class="piper" kp="100" kv="10"/>
  </actuator>
</mujoco>
