<?xml version="1.0" encoding="utf-8"?>
<robot name="piper_description">
  <link
    name="base_link">
    <inertial>
      <origin
        xyz="-0.00473641164191482 2.56829134630247E-05 0.041451518036016"
        rpy="0 0 0" />
      <mass
        value="0.333893486740112" />
      <inertia
        ixx="0.000254953479570424"
        ixy="2.06931238580746E-07"
        ixz="7.30912474718368E-06"
        iyy="0.00027202099920186"
        iyz="2.65131745382267E-07"
        izz="0.000276534627629623" />
    </inertial>
    <visual>
      <origin
        xyz="0 0 0"
        rpy="0 0 0" />
      <geometry>
        <mesh
          filename="/home/hello-robot/code/robot/robot/arm/models/meshes/base_link.STL" />
      </geometry>
      <material
        name="">
        <color
          rgba="0.792156862745098 0.819607843137255 0.933333333333333 1" />
      </material>
    </visual>
    <collision>
      <origin
        xyz="0 0 0"
        rpy="0 0 0" />
      <geometry>
        <mesh
          filename="/home/hello-robot/code/robot/robot/arm/models/meshes/base_link.STL" />
      </geometry>
    </collision>
  </link>
  <link
    name="link1">
    <inertial>
      <origin
        xyz="0.000121504734057468 0.000104632162460536 -0.00438597309559853"
        rpy="0 0 0" />
      <mass
        value="0.215052383265765" />
      <inertia
        ixx="0.000109639007860341"
        ixy="2.50631260865109E-07"
        ixz="-1.89352789149844E-07"
        iyy="9.95612262461418E-05"
        iyz="1.00634716976093E-08"
        izz="0.000116363910317385" />
    </inertial>
    <visual>
      <origin
        xyz="0 0 0"
        rpy="0 0 0" />
      <geometry>
        <mesh
          filename="/home/hello-robot/code/robot/robot/arm/models/meshes/link1.STL" />
      </geometry>
      <material
        name="">
        <color
          rgba="0.792156862745098 0.819607843137255 0.933333333333333 1" />
      </material>
    </visual>
    <collision>
      <origin
        xyz="0 0 0"
        rpy="0 0 0" />
      <geometry>
        <mesh
          filename="/home/hello-robot/code/robot/robot/arm/models/meshes/link1.STL" />
      </geometry>
    </collision>
  </link>
  <joint
    name="joint1"
    type="revolute">
    <origin
      xyz="0 0 0.123"
      rpy="0 0 0" />
    <parent
      link="base_link" />
    <child
      link="link1" />
    <axis
      xyz="0 0 1" />
    <limit
      lower="-2.618"
      upper="0.25"
      effort="100"
      velocity="5" />
  </joint>
  <link
    name="link2">
    <inertial>
      <origin
        xyz="0.198666145229743 -0.010926924140076 0.00142121714502687"
        rpy="0 0 0" />
      <mass
        value="0.463914239236335" />
      <inertia
        ixx="0.000214137415059993"
        ixy="7.26120579340088E-05"
        ixz="-9.88224861011274E-07"
        iyy="0.00100030277518254"
        iyz="-1.32818212212246E-06"
        izz="0.00104417184176783" />
    </inertial>
    <visual>
      <origin
        xyz="0 0 0"
        rpy="0 0 0" />
      <geometry>
        <mesh
          filename="/home/hello-robot/code/robot/robot/arm/models/meshes/link2.STL" />
      </geometry>
      <material
        name="">
        <color
          rgba="0.792156862745098 0.819607843137255 0.933333333333333 1" />
      </material>
    </visual>
    <collision>
      <origin
        xyz="0 0 0"
        rpy="0 0 0" />
      <geometry>
        <mesh
          filename="/home/hello-robot/code/robot/robot/arm/models/meshes/link2.STL" />
      </geometry>
    </collision>
  </link>
  <joint
    name="joint2"
    type="revolute">
    <origin
      xyz="0 0 0"
      rpy="1.5708 -0.10095 -3.1416" />
    <parent
      link="link1" />
    <child
      link="link2" />
    <axis
      xyz="0 0 1" />
    <limit
      lower="0"
      upper="3.14"
      effort="100"
      velocity="5" />
  </joint>
  <link
    name="link3">
    <inertial>
      <origin
        xyz="-0.0202737662122021 -0.133914995944595 -0.000458682652737356"
        rpy="0 0 0" />
      <mass
        value="0.219942452993132" />
      <inertia
        ixx="0.00018953849076141"
        ixy="-8.05719205057736E-06"
        ixz="5.10255053956334E-07"
        iyy="7.1424497082494E-05"
        iyz="8.89044974368937E-07"
        izz="0.000201212938725775" />
    </inertial>
    <visual>
      <origin
        xyz="0 0 0"
        rpy="0 0 0" />
      <geometry>
        <mesh
          filename="/home/hello-robot/code/robot/robot/arm/models/meshes/link3.STL" />
      </geometry>
      <material
        name="">
        <color
          rgba="0.792156862745098 0.819607843137255 0.933333333333333 1" />
      </material>
    </visual>
    <collision>
      <origin
        xyz="0 0 0"
        rpy="0 0 0" />
      <geometry>
        <mesh
          filename="/home/hello-robot/code/robot/robot/arm/models/meshes/link3.STL" />
      </geometry>
    </collision>
  </link>
  <joint
    name="joint3"
    type="revolute">
    <origin
      xyz="0.28503 0 0"
      rpy="0 0 -1.759" />
    <parent
      link="link2" />
    <child
      link="link3" />
    <axis
      xyz="0 0 1" />
    <limit
      lower="-2.967"
      upper="0"
      effort="100"
      velocity="5" />
  </joint>
  <link
    name="link4">
    <inertial>
      <origin
        xyz="-9.66635791618542E-05 0.000876064475651083 -0.00496880904640868"
        rpy="0 0 0" />
      <mass
        value="0.131814339939458" />
      <inertia
        ixx="3.96965423235175E-05"
        ixy="-2.32268338444837E-08"
        ixz="-1.14702090783249E-07"
        iyy="5.13319789853892E-05"
        iyz="9.92852686264567E-08"
        izz="4.14768131680711E-05" />
    </inertial>
    <visual>
      <origin
        xyz="0 0 0"
        rpy="0 0 0" />
      <geometry>
        <mesh
          filename="/home/hello-robot/code/robot/robot/arm/models/meshes/link4.STL" />
      </geometry>
      <material
        name="">
        <color
          rgba="0.792156862745098 0.819607843137255 0.933333333333333 1" />
      </material>
    </visual>
    <collision>
      <origin
        xyz="0 0 0"
        rpy="0 0 0" />
      <geometry>
        <mesh
          filename="/home/hello-robot/code/robot/robot/arm/models/meshes/link4.STL" />
      </geometry>
    </collision>
  </link>
  <joint
    name="joint4"
    type="revolute">
    <origin
      xyz="-0.021984 -0.25075 0"
      rpy="1.5708 0 0" />
    <parent
      link="link3" />
    <child
      link="link4" />
    <axis
      xyz="0 0 1" />
    <limit
      lower="-1.745"
      upper="1.745"
      effort="100"
      velocity="5" />
  </joint>
  <link
    name="link5">
    <inertial>
      <origin
        xyz="-4.10554118924211E-05 -0.0566486692356075 -0.0037205791677906"
        rpy="0 0 0" />
      <mass
        value="0.134101341225523" />
      <inertia
        ixx="4.10994130543451E-05"
        ixy="-2.06433983793957E-08"
        ixz="1.29591347668502E-10"
        iyy="5.27723004189144E-05"
        iyz="1.9140716904272E-07"
        izz="4.60418752810541E-05" />
    </inertial>
    <visual>
      <origin
        xyz="0 0 0"
        rpy="0 0 0" />
      <geometry>
        <mesh
          filename="/home/hello-robot/code/robot/robot/arm/models/meshes/link5.STL" />
      </geometry>
      <material
        name="">
        <color
          rgba="0.792156862745098 0.819607843137255 0.933333333333333 1" />
      </material>
    </visual>
    <collision>
      <origin
        xyz="0 0 0"
        rpy="0 0 0" />
      <geometry>
        <mesh
          filename="/home/hello-robot/code/robot/robot/arm/models/meshes/link5.STL" />
      </geometry>
    </collision>
  </link>
  <joint
    name="joint5"
    type="revolute">
    <origin
      xyz="0 0 0"
      rpy="-1.5708 0 0" />
    <parent
      link="link4" />
    <child
      link="link5" />
    <axis
      xyz="0 0 1" />
    <limit
      lower="-1.22"
      upper="1.22"
      effort="100"
      velocity="5" />
  </joint>
  <link
    name="link6">
    <inertial>
      <origin
        xyz="-8.82590762930069E-05 9.0598378529832E-06 -0.002"
        rpy="0 0 0" />
      <mass
        value="0.00699089613564366" />
      <inertia
        ixx="5.43015540542155E-07"
        ixy="-1.98305403089247E-22"
        ixz="-7.2791893904596E-23"
        iyy="5.43015540542155E-07"
        iyz="-3.4146026640245E-24"
        izz="1.06738869138926E-06" />
    </inertial>
    <visual>
      <origin
        xyz="0 0 0"
        rpy="0 0 0" />
      <geometry>
        <mesh
          filename="/home/hello-robot/code/robot/robot/arm/models/meshes/link6.STL" />
      </geometry>
      <material
        name="">
        <color
          rgba="0.898039215686275 0.917647058823529 0.929411764705882 1" />
      </material>
    </visual>
    <collision>
      <origin
        xyz="0 0 0"
        rpy="0 0 0" />
      <geometry>
        <mesh
          filename="/home/hello-robot/code/robot/robot/arm/models/meshes/link6.STL" />
      </geometry>
    </collision>
  </link>
  <joint
    name="joint6"
    type="revolute">
    <origin
      xyz="8.8259E-05 -0.091 0"
      rpy="1.5708 -0.7 0" />
    <parent
      link="link5" />
    <child
      link="link6" />
    <axis
      xyz="0 0 1" />
    <limit
      lower="-2.7944"
      upper="1.4"
      effort="100"
      velocity="3" />
  </joint>
  <link
    name="gripper_base">
    <inertial>
      <origin
        xyz="-0.000183807162235591 8.05033155577911E-05 0.0321436689908876"
        rpy="0 0 0" />
      <mass
        value="0.145318531013916" />
      <inertia
        ixx="0.000101740348396288"
        ixy="-1.43961090652723E-07"
        ixz="-8.72352812740139E-08"
        iyy="4.16518088621566E-05"
        iyz="3.27712901952435E-08"
        izz="0.000118691325723675" />
    </inertial>
    <visual>
      <origin
        xyz="0 0 0"
        rpy="0 0 0" />
      <geometry>
        <mesh
          filename="/home/hello-robot/code/robot/robot/arm/models/meshes/gripper_base.STL" />
      </geometry>
      <material
        name="">
        <color
          rgba="0.792156862745098 0.819607843137255 0.933333333333333 1" />
      </material>
    </visual>
    <collision>
      <origin
        xyz="0 0 0"
        rpy="0 0 0" />
      <geometry>
        <mesh
          filename="/home/hello-robot/code/robot/robot/arm/models/meshes/gripper_base.STL" />
      </geometry>
    </collision>
  </link>
  <joint
    name="joint6_to_gripper_base"
    type="fixed">
    <origin
      xyz="0 0 0"
      rpy="0 0 0" />
    <parent
      link="link6" />
    <child
      link="gripper_base" />
  </joint>
  <link
    name="link7">
    <inertial>
      <origin
        xyz="0.00065123185041968 -0.0491929869131989 0.00972258769184025"
        rpy="0 0 0" />
      <mass
        value="0.0303534920715906" />
      <inertia
        ixx="1.13870358991284E-05"
        ixy="4.2853410993302E-07"
        ixz="-6.45170690459141E-08"
        iyy="6.26108891787743E-06"
        iyz="1.5729036212893E-06"
        izz="1.57822030592869E-05" />
    </inertial>
    <visual>
      <origin
        xyz="0 0 0"
        rpy="0 0 0" />
      <geometry>
        <mesh
          filename="/home/hello-robot/code/robot/robot/arm/models/meshes/link7.STL" />
      </geometry>
      <material
        name="">
        <color
          rgba="0.792156862745098 0.819607843137255 0.933333333333333 1" />
      </material>
    </visual>
    <collision>
      <origin
        xyz="0 0 0"
        rpy="0 0 0" />
      <geometry>
        <mesh
          filename="/home/hello-robot/code/robot/robot/arm/models/meshes/link7.STL" />
      </geometry>
    </collision>
  </link>
  <joint
    name="joint7"
    type="prismatic">
    <origin
      xyz="0 0 0.1358"
      rpy="1.5708 0 0" />
    <parent
      link="gripper_base" />
    <child
      link="link7" />
    <axis
      xyz="0 0 1" />
    <limit
      lower="0"
      upper="0.035"
      effort="10"
      velocity="1" />
  </joint>
  <link
    name="link8">
    <inertial>
      <origin
        xyz="0.000651231850419722 -0.0491929869131991 0.00972258769184024"
        rpy="0 0 0" />
      <mass
        value="0.0303534920715904" />
      <inertia
        ixx="1.13870358991283E-05"
        ixy="4.28534109932964E-07"
        ixz="-6.45170690459078E-08"
        iyy="6.26108891787742E-06"
        iyz="1.57290362128933E-06"
        izz="1.57822030592867E-05" />
    </inertial>
    <visual>
      <origin
        xyz="0 0 0"
        rpy="0 0 0" />
      <geometry>
        <mesh
          filename="/home/hello-robot/code/robot/robot/arm/models/meshes/link8.STL" />
      </geometry>
      <material
        name="">
        <color
          rgba="0.792156862745098 0.819607843137255 0.933333333333333 1" />
      </material>
    </visual>
    <collision>
      <origin
        xyz="0 0 0"
        rpy="0 0 0" />
      <geometry>
        <mesh
          filename="/home/hello-robot/code/robot/robot/arm/models/meshes/link8.STL" />
      </geometry>
    </collision>
  </link>
  <joint
    name="joint8"
    type="prismatic">
    <origin
      xyz="0 0 0.1358"
      rpy="1.5708 0 -3.1416" />
    <parent
      link="gripper_base" />
    <child
      link="link8" />
    <axis
      xyz="0 0 -1" />
    <limit
      lower="-0.035"
      upper="0"
      effort="10"
      velocity="1" />
  </joint>
</robot>